<mujoco>
	<!-- The box size is 2.5 cm -->
            <geom name='rubik:box_0_0_0' pos='-0.0125 -0.0125 -0.0125' euler='0 0 0' type='mesh' mesh='rubik:box_mesh'  material='Black' class='rubik:box'/>
            <geom name='rubik:box_0_0_0_y' type='box' size='0.01 0.01 .0001' material='Yellow' pos='0 0 -0.0125' class='rubik:box'/>
            <geom name='rubik:box_0_0_0_b' type='box' size='.0001 0.01 0.01' material='Blue' pos='-0.0125 0 0' class='rubik:box'/>
            <geom name='rubik:box_0_0_0_o' type='box' size='0.01 .0001 0.01' material='Orange' pos='0 -0.0125 0' class='rubik:box'/>
            <site name='rubik:cube_center'  type='box' size='0.005 0.005 0.005' pos='0.0125 0.0125 0.0125' />

            <body name='rubik:box_1_0_0' pos='0.025 0 0'>
                <geom name='rubik:box_1_0_0' pos='-0.0125 -0.0125 -0.0125' euler='0 0 0' type='mesh' mesh='rubik:box_mesh'  material='Black' class='rubik:box'/>
                <geom name='rubik:box_1_0_0_y' type='box' size='0.01 0.01 .0001' material='Yellow' pos='0 0 -0.0125' class='rubik:box'/>
                <geom name='rubik:box_1_0_0_g' type='box' size='.0001 0.01 0.01' material='Green' pos='0.0125 0 0' class='rubik:box'/>
                <geom name='rubik:box_1_0_0_o' type='box' size='0.01 .0001 0.01' material='Orange' pos='0 -0.0125 0' class='rubik:box'/>
                <joint name='rubik:ball_joint_1_0_0' type='ball' pos='-0.0125 0.0125 0.0125' class='rubik:ball_joint'/>
            </body>

            <body name='rubik:box_0_1_0' pos='0 0.025 0'>
                <geom name='rubik:box_0_1_0' pos='-0.0125 -0.0125 -0.0125' euler='0 0 0' type='mesh' mesh='rubik:box_mesh' material='Black' class='rubik:box'/>
                <geom name='rubik:box_0_1_0_y' type='box' size='0.01 0.01 .0001' material='Yellow' pos='0 0 -0.0125' class='rubik:box'/>
                <geom name='rubik:box_0_1_0_b' type='box' size='.0001 0.01 0.01' material='Blue' pos='-0.0125 0 0' class='rubik:box'/>
                <geom name='rubik:box_0_1_0_r' type='box' size='0.01 .0001 0.01' material='Red' pos='0 0.0125 0' class='rubik:box'/>
                <joint name='rubik:ball_joint_0_1_0' type='ball' pos='0.0125 -0.0125 0.0125' class='rubik:ball_joint'/>
            </body>

            <body name='rubik:box_1_1_0' pos='0.025 0.025 0'>
                <geom name='rubik:box_1_1_0' pos='-0.0125 -0.0125 -0.0125' euler='0 0 0' type='mesh' mesh='rubik:box_mesh' material='Black' class='rubik:box'/>
                <geom name='rubik:box_1_1_0_y' type='box' size='0.01 0.01 .0001' material='Yellow' pos='0 0 -0.0125' class='rubik:box'/>
                <geom name='rubik:box_1_1_0_g' type='box' size='.0001 0.01 0.01' material='Green' pos='0.0125 0 0' class='rubik:box'/>
                <geom name='rubik:box_1_1_0_r' type='box' size='0.01 .0001 0.01' material='Red' pos='0 0.0125 0' class='rubik:box'/>
                <joint name='rubik:ball_joint_1_1_0' type='ball' pos='-0.0125 -0.0125 0.0125' class='rubik:ball_joint'/>
            </body>

            <body name='rubik:box_0_0_1' pos='0 0 0.025'>
                <geom name='rubik:box_0_0_1' pos='-0.0125 -0.0125 -0.0125' euler='0 0 0' type='mesh' mesh='rubik:box_mesh' material='Black' class='rubik:box'/>
                <geom name='rubik:box_0_0_1_w' type='box' size='0.01 0.01 .0001' material='White' pos='0 0 0.0125' class='rubik:box'/>
                <geom name='rubik:box_0_0_1_b' type='box' size='.0001 0.01 0.01' material='Blue' pos='-0.0125 0 0' class='rubik:box'/>
                <geom name='rubik:box_0_0_1_o' type='box' size='0.01 .0001 0.01' material='Orange' pos='0 -0.0125 0' class='rubik:box'/>
                <joint name='rubik:ball_joint_0_0_1' type='ball' pos='0.0125 0.0125 -0.0125' class='rubik:ball_joint'/>
            </body>


            <body name='rubik:box_1_0_1' pos='0.025 0 0.025'>
                <geom name='rubik:box_1_0_1' pos='-0.0125 -0.0125 -0.0125' euler='0 0 0' type='mesh' mesh='rubik:box_mesh' material='Black' class='rubik:box'/>
                <geom name='rubik:box_1_0_1_w' type='box' size='0.01 0.01 .0001' material='White' pos='0 0 0.0125' class='rubik:box'/>
                <geom name='rubik:box_1_0_1_g' type='box' size='.0001 0.01 0.01' material='Green' pos='0.0125 0 0' class='rubik:box'/>
                <geom name='rubik:box_1_0_1_o' type='box' size='0.01 .0001 0.01' material='Orange' pos='0 -0.0125 0' class='rubik:box'/>
                <joint name='rubik:ball_joint_1_0_1' type='ball' pos='-0.0125 0.0125 -0.0125' class='rubik:ball_joint'/>
            </body>

            <body name='rubik:box_0_1_1' pos='0 0.025 0.025'>
                <geom name='rubik:box_0_1_1' pos='-0.0125 -0.0125 -0.0125' euler='0 0 0' type='mesh' mesh='rubik:box_mesh' material='Black' class='rubik:box'/>
                <geom name='rubik:box_0_1_1_w' type='box' size='0.01 0.01 .0001' material='White' pos='0 0 0.0125' class='rubik:box'/>
                <geom name='rubik:box_0_1_1_b' type='box' size='.0001 0.01 0.01' material='Blue' pos='-0.0125 0 0' class='rubik:box'/>
                <geom name='rubik:box_0_1_1_r' type='box' size='0.01 .0001 0.01' material='Red' pos='0 0.0125 0' class='rubik:box'/>
                <joint name='rubik:ball_joint_0_1_1' type='ball' pos='0.0125 -0.0125 -0.0125' class='rubik:ball_joint'/>
            </body>

            <body name='rubik:box_1_1_1' pos='0.025 0.025 0.025'>
                <geom name='rubik:box_1_1_1' pos='-0.0125 -0.0125 -0.0125' euler='0 0 0' type='mesh' mesh='rubik:box_mesh' material='Black' class='rubik:box'/>
                <geom name='rubik:box_1_1_1_w' type='box' size='0.01 0.01 .0001' material='White' pos='0 0 0.0125' class='rubik:box'/>
                <geom name='rubik:box_1_1_1_g' type='box' size='.0001 0.01 0.01' material='Green' pos='0.0125 0 0' class='rubik:box'/>
                <geom name='rubik:box_1_1_1_r' type='box' size='0.01 .0001 0.01' material='Red' pos='0 0.0125 0' class='rubik:box'/>
                <joint name='rubik:ball_joint_1_1_1' type='ball' pos='-0.0125 -0.0125 -0.0125' class='rubik:ball_joint'/>
            </body>
</mujoco>
